<mujocoinclude>
    <body name="base_footprint" pos="0 0 0.1" childclass="husky">
        <joint type="free" stiffness="0" damping="0" frictionloss="0" armature="0" />

        <body name="base" pos="0 0 0">
            <inertial pos="-0.00065 -0.085 0.062"  mass="46.034" fullinertia="0.6022 1.7386 2.0296 -0.02364 -0.1197 -0.001544"/>
            <geom class="husky_collision" size="0.4937 0.28545 0.061875" pos="0 0 0.061875" type="box"/>
            <geom class="husky_collision" size="0.39496 0.28545 0.051875" pos="0 0 0.175625" type="box"/>
            <geom class="husky_visual" pos="0.272 0 0.245" type="mesh" mesh="user_rail" material="black"/>
            <geom class="husky_visual" pos="0.0812 0 0.245" type="mesh" mesh="top_plate" material="black"/>
            <geom class="husky_visual" pos="-0.48 0 0.091" quat="0 0 1 0" type="mesh" mesh="bumper" rgba="0.2 0.2 0.2 1.0"/>
            <geom class="husky_visual" pos="0.48 0 0.091" type="mesh" mesh="bumper" rgba="0.2 0.2 0.2 1.0"/>
            <geom class="husky_visual" pos="0 0 0" type="mesh" mesh="base_link" rgba="0.8 0.8 0.0 1.0"/>
            <geom class="husky_visual" pos="0 0 0" type="mesh" mesh="top_chassis" rgba="0.8 0.8 0.0 1.0"/>
            <site name="husky_site"  size = "0.005" rgba = ".1 .1 .9 1" type = "sphere" />

            <body name="front_left_wheel" pos="0.256 0.2854 0.03282">
                <inertial pos="0 0 0" quat="0.707107 0 0 0.707107" mass="2.637" diaginertia="0.04411 0.02467 0.02467"/>
                <joint name="front_left_wheel" type="hinge" pos="0 0 0" axis="0 1 0"/>
                <geom class="husky_visual" pos="0 0 0" quat="0 0 0 1" mesh="wheel" material="black"/>
                <geom class="husky_collision" size="0.1651 0.05715" quat="0.707107 0.707106 0 0" type="cylinder"/>
            </body>

            <body name="front_right_wheel" pos="0.256 -0.2854 0.03282">
                <inertial pos="0 0 0" quat="0.707107 0 0 0.707107" mass="2.637" diaginertia="0.04411 0.02467 0.02467"/>
                <joint name="front_right_wheel" type="hinge" pos="0 0 0" axis="0 1 0"/>
                <geom class="husky_visual" pos="0 0 0" quat="0 0 0 1" mesh="wheel" material="black"/>
                <geom class="husky_collision" size="0.1651 0.05715" quat="0.707107 0.707106 0 0" type="cylinder"/>
            </body>

            <body name="rear_left_wheel" pos="-0.256 0.2854 0.03282">
                <inertial pos="0 0 0" quat="0.707107 0 0 0.707107" mass="2.637" diaginertia="0.04411 0.02467 0.02467"/>
                <joint name="rear_left_wheel" type="hinge" pos="0 0 0" axis="0 1 0"/>
                <geom class="husky_visual" pos="0 0 0" quat="0 0 0 1" mesh="wheel" material="black"/>
                <geom class="husky_collision" size="0.1651 0.05715" quat="0.707107 0.707106 0 0" type="cylinder"/>
            </body>

            <body name="rear_right_wheel" pos="-0.256 -0.2854 0.03282">
                <inertial pos="0 0 0" quat="0.707107 0 0 0.707107" mass="2.637" diaginertia="0.04411 0.02467 0.02467"/>
                <joint name="rear_right_wheel" type="hinge" pos="0 0 0" axis="0 1 0" />
                <geom class="husky_visual" pos="0 0 0" quat="0 0 0 1" mesh="wheel" material="black"/>
                <geom class="husky_collision" size="0.1651 0.05715" quat="0.707107 0.707106 0 0" type="cylinder"/>
            </body>
        </body>
    </body>
</mujocoinclude>